[2025-06-11T07:52:57.495+0000] {local_task_job_runner.py:123} INFO - ::group::Pre task execution logs
[2025-06-11T07:52:57.512+0000] {taskinstance.py:2631} INFO - Dependencies all met for dep_context=non-requeueable deps ti=<TaskInstance: my_dag.save_data manual__2025-06-11T07:52:35.403637+00:00 [queued]>
[2025-06-11T07:52:57.524+0000] {taskinstance.py:2631} INFO - Dependencies all met for dep_context=requeueable deps ti=<TaskInstance: my_dag.save_data manual__2025-06-11T07:52:35.403637+00:00 [queued]>
[2025-06-11T07:52:57.526+0000] {taskinstance.py:2884} INFO - Starting attempt 1 of 2
[2025-06-11T07:52:57.550+0000] {taskinstance.py:2907} INFO - Executing <Task(PythonOperator): save_data> on 2025-06-11 07:52:35.403637+00:00
[2025-06-11T07:52:57.561+0000] {standard_task_runner.py:72} INFO - Started process 114 to run task
[2025-06-11T07:52:57.569+0000] {standard_task_runner.py:104} INFO - Running: ['airflow', 'tasks', 'run', 'my_dag', 'save_data', 'manual__2025-06-11T07:52:35.403637+00:00', '--job-id', '16', '--raw', '--subdir', 'DAGS_FOLDER/dag.py', '--cfg-path', '/tmp/tmpj0e6mtbu']
[2025-06-11T07:52:57.574+0000] {standard_task_runner.py:105} INFO - Job 16: Subtask save_data
[2025-06-11T07:52:57.631+0000] {task_command.py:467} INFO - Running <TaskInstance: my_dag.save_data manual__2025-06-11T07:52:35.403637+00:00 [running]> on host 8b57c8cca04f
[2025-06-11T07:52:57.715+0000] {taskinstance.py:3157} INFO - Exporting env vars: AIRFLOW_CTX_DAG_OWNER='airflow' AIRFLOW_CTX_DAG_ID='my_dag' AIRFLOW_CTX_TASK_ID='save_data' AIRFLOW_CTX_EXECUTION_DATE='2025-06-11T07:52:35.403637+00:00' AIRFLOW_CTX_TRY_NUMBER='1' AIRFLOW_CTX_DAG_RUN_ID='manual__2025-06-11T07:52:35.403637+00:00'
[2025-06-11T07:52:57.718+0000] {taskinstance.py:740} INFO - ::endgroup::
[2025-06-11T07:52:57.732+0000] {logging_mixin.py:190} INFO - Reading coutries data from /opt/airflow/trusted/cleaned_data.csv
[2025-06-11T07:52:57.788+0000] {logging_mixin.py:190} INFO - An error occurred while saving data to MySQL: (pymysql.err.OperationalError) (1049, "Unknown database 'user'")
(Background on this error at: https://sqlalche.me/e/14/e3q8)
[2025-06-11T07:52:57.790+0000] {logging_mixin.py:190} INFO - Reading country currency data from /opt/airflow/foundation/structured_data.csv
[2025-06-11T07:52:57.826+0000] {logging_mixin.py:190} INFO - An error occurred while saving data to MySQL: (pymysql.err.OperationalError) (1049, "Unknown database 'user'")
(Background on this error at: https://sqlalche.me/e/14/e3q8)
[2025-06-11T07:52:57.828+0000] {logging_mixin.py:190} INFO - Reading currency data from /opt/airflow/trusted/currencies.csv
[2025-06-11T07:52:57.838+0000] {logging_mixin.py:190} INFO - An error occurred while saving data to MySQL: (pymysql.err.OperationalError) (1049, "Unknown database 'user'")
(Background on this error at: https://sqlalche.me/e/14/e3q8)
[2025-06-11T07:52:57.840+0000] {python.py:240} INFO - Done. Returned value was: None
[2025-06-11T07:52:57.847+0000] {taskinstance.py:349} INFO - ::group::Post task execution logs
[2025-06-11T07:52:57.850+0000] {taskinstance.py:361} INFO - Marking task as SUCCESS. dag_id=my_dag, task_id=save_data, run_id=manual__2025-06-11T07:52:35.403637+00:00, execution_date=20250611T075235, start_date=20250611T075257, end_date=20250611T075257
[2025-06-11T07:52:57.908+0000] {local_task_job_runner.py:266} INFO - Task exited with return code 0
[2025-06-11T07:52:57.922+0000] {taskinstance.py:3924} INFO - 0 downstream tasks scheduled from follow-on schedule check
[2025-06-11T07:52:57.925+0000] {local_task_job_runner.py:245} INFO - ::endgroup::
